Workbook

Sheet Korsatma
A1: Ustun (label) | B1: Nima yoziladi / qanday tanlanadi
A2: Savol | B2: Q raqami (avtomatik to'ldirilgan).
A3: Ball | B3: Savolning ball qiymati (3 / 4 / 6) — to'ldirilgan.
A4: Qiyinchilik | B4: Oson = asosiy bilim/eslab qolish; O'rta = qo'llash/tahlil/bog'lash; Qiyin = ko'p bosqichli, murakkab, yuqori tahlil. (Kohort bo'lsa p-qiymat bilan tasdiqlanadi.)
A5: Strand | B5: 3 katta blokdan biri (Son / Geometriya / Mantiq).
A6: Mavzu | B6: Aniq mavzu (issiqlik xaritasi shu bo'yicha). Ro'yxatdan tanlang.
A7: Quyi mavzu | B7: Erkin izoh — aniqroq quyi mavzu (diagnostika uchun).
A8: Asosiy ko'nikma | B8: Savol BIRINCHI navbatda qaysi ko'nikmani o'lchaydi (radar shu bo'yicha).
A9: Bloom darajasi | B9: Kognitiv daraja: eslab qolish -> tushunish -> qo'llash -> tahlil -> baholash -> yaratish.
A10: Fikrlash turi | B10: Deduktiv (qoidadan natija), Induktiv (misoldan qoida), Analitik, Fazoviy yoki Yo'q.
A11: Sinf darajasi | B11: Savol 7-sinf, undan past yoki yuqorimi (gap tahlili shu bo'yicha).
A12: Xalqaro framework | B12: Savol qaysi xalqaro domenga mos (PISA / TIMSS / Kangaroo). Qamrov shu bo'yicha.
... A19: TAMOYIL | B19: Indikator faqat shu jadvaldagi label'lardan kelib chiqsa beriladi. n<3 (yetarli savol yo'q) bo'lsa — aniq raqam emas, sifatli baho + 'past ishonch'. Vaqt/percentile/guruh o'rtachasi — faqat o'lchansa/kohort bo'lsa.

Sheet Savollar
A1: Savol | B1: Ball | C1: Qiyinchilik | D1: Strand (katta blok) | E1: Mavzu | F1: Quyi mavzu (izoh) | G1: Asosiy ko'nikma | H1: Bloom darajasi | I1: Fikrlash turi | J1: Sinf darajasi | K1: Xalqaro framework | L1: Natija | M1: Olingan ball | N1: Xato turi | O1: Yechish vaqti (s) | P1: Dalil / nimani ko'rsatdi
A2: Q1 | B2: 3 | C2: O'rta | D2: Son va amallar | E2: Algebra | F2: So'z birikmasini ifodaga o'girish | G2: Konseptual tushunish | H2: Tushunish | I2: Analitik | J2: 7-sinf | K2: TIMSS: Algebra | M2: =IF($L2="","",IF($L2="To'g'ri",$B2,IF($L2="Qisman","",0)))
A3: Q2 | B3: 3 | C3: Oson | D3: Son va amallar | E3: Algebra | F3: Ifoda qiymatini hisoblash (a=4) | G3: Protsedural ravonlik | H3: Qo'llash | I3: Analitik | J3: 7-sinf | K3: TIMSS: Algebra | M3: =IF($L3="","",IF($L3="To'g'ri",$B3,IF($L3="Qisman","",0)))
A4: Q3 | B4: 3 | C4: Oson | D4: Son va amallar | E4: Kasr amallari | F4: To'g'ri kasrni natural songa bo'lish | G4: Protsedural ravonlik | H4: Qo'llash | I4: Analitik | J4: 7-sinf | K4: TIMSS: Number | M4: =IF($L4="","",IF($L4="To'g'ri",$B4,IF($L4="Qisman","",0)))
A5: Q4 | B5: 3 | C5: O'rta | D5: Son va amallar | E5: Nisbat va proporsiya | F5: Nisbatni soddalashtirish | G5: Protsedural ravonlik | H5: Qo'llash | I5: Analitik | J5: 7-sinf | K5: TIMSS: Number | M5: =IF($L5="","",IF($L5="To'g'ri",$B5,IF($L5="Qisman","",0)))
A6: Q5 | B6: 3 | C6: O'rta | D6: Son va amallar | E6: Foiz | F6: Foiz orqali butun sonni topish | G6: Konseptual tushunish | H6: Qo'llash | I6: Analitik | J6: 7-sinf | K6: TIMSS: Number | M6: =IF($L6="","",IF($L6="To'g'ri",$B6,IF($L6="Qisman","",0)))
A7: Q6 | B7: 3 | C7: O'rta | D7: Son va amallar | E7: Nisbat va proporsiya | F7: Nisbat/kasr/foiz ekvivalenti | G7: Konseptual tushunish | H7: Tushunish | I7: Analitik | J7: 7-sinf | K7: TIMSS: Number | M7: =IF($L7="","",IF($L7="To'g'ri",$B7,IF($L7="Qisman","",0)))
A8: Q7 | B8: 3 | C8: O'rta | D8: Son va amallar | E8: O'nli kasr | F8: Kasr va o'nli kasrni taqqoslash | G8: Konseptual tushunish | H8: Tushunish | I8: Analitik | J8: 7-sinf | K8: TIMSS: Number | M8: =IF($L8="","",IF($L8="To'g'ri",$B8,IF($L8="Qisman","",0)))
A9: Q8 | B9: 3 | C9: O'rta | D9: Geometriya va o'lchov | E9: Geometriya | F9: To'rtburchak burchaklari (360 daraja) | G9: Konseptual tushunish | H9: Qo'llash | I9: Analitik | J9: 7-sinf | K9: TIMSS: Geometry | M9: =IF($L9="","",IF($L9="To'g'ri",$B9,IF($L9="Qisman","",0)))
A10: Q9 | B10: 3 | C10: O'rta | D10: Son va amallar | E10: Kasr amallari | F10: Natural sonni kasrga bo'lish | G10: Protsedural ravonlik | H10: Qo'llash | I10: Analitik | J10: 7-sinf | K10: TIMSS: Number | M10: =IF($L10="","",IF($L10="To'g'ri",$B10,IF($L10="Qisman","",0)))
A11: Q10 | B11: 3 | C11: O'rta | D11: Geometriya va o'lchov | E11: Geometriya | F11: Aylana uzunligi (C=pi*d) | G11: Protsedural ravonlik | H11: Qo'llash | I11: Analitik | J11: 7-sinf | K11: TIMSS: Geometry | M11: =IF($L11="","",IF($L11="To'g'ri",$B11,IF($L11="Qisman","",0)))
A12: Q11 | B12: 4 | C12: O'rta | D12: Son va amallar | E12: Algebra | F12: O'xshash hadlarni ixchamlash | G12: Protsedural ravonlik | H12: Qo'llash | I12: Analitik | J12: 7-sinf | K12: TIMSS: Algebra | M12: =IF($L12="","",IF($L12="To'g'ri",$B12,IF($L12="Qisman","",0)))
A13: Q12 | B13: 4 | C13: O'rta | D13: Son va amallar | E13: Foiz | F13: Narxni foizga oshirish (+20%) | G13: Konseptual tushunish | H13: Qo'llash | I13: Analitik | J13: 7-sinf | K13: PISA: Miqdor | M13: =IF($L13="","",IF($L13="To'g'ri",$B13,IF($L13="Qisman","",0)))
... A26: Q25 | B26: 6 | C26: Qiyin | D26: Geometriya va o'lchov | E26: Geometriya | F26: Murakkab shakl yuzi (to'rtburchak + yarim doira) | G26: Fazoviy fikrlash | H26: Tahlil | I26: Fazoviy | J26: 7-sinf | K26: PISA: Fazo va shakl | M26: =IF($L26="","",IF($L26="To'g'ri",$B26,IF($L26="Qisman","",0)))
A28: Namuna: Q1 (to'g'ri) va Q19 (xato) to'ldirilgan. Qolganini shu mantiqda to'ldiring. Sariq = namuna.

Sheet Hisob_auto
A1: AVTOMATIK HISOB — har bir raqam 'Savollar' varag'idagi label'lardan chiqadi
A3: UMUMIY KO'RSATKICHLAR
A4: Jami savollar | B4: =COUNTA(Savollar!$A$2:$A$26) -> 25
A5: Jami ball | B5: =SUM(Savollar!$B$2:$B$26) -> 100
A6: Olingan ball (xom) | B6: =SUM(Savollar!$M$2:$M$26) -> 0
A7: To'g'ri javoblar soni | B7: =COUNTIF(Savollar!$L$2:$L$26,"To'g'ri") -> 0
A8: Joriy ball foizi | B8: =IFERROR(ROUND(B6/B5*100,0),"") -> 0 | E8: Olingan / Jami x 100
A9: Tuzatilgan baho | B9: =IFERROR(B6+SUMIFS(Savollar!$B$2:$B$26,Savollar!$N$2:$N$26,"Texnik"),"") -> 0 | E9: Xom + texnik xato ballari (qaytariladigan)
A11: QIYINCHILIK & KDI
A12: Toifa | B12: Savollar | C12: To'g'ri | D12: Foiz % | E12: Og'irlik
A13: Oson | B13: =COUNTIF(Savollar!$C$2:$C$26,"Oson") -> 2 | C13: =COUNTIFS(Savollar!$C$2:$C$26,"Oson",Savollar!$L$2:$L$26,"To'g'ri") -> 0 | D13: =IFERROR(ROUND(C13/B13*100,0),"") -> 0 | E13: 1
A14: O'rta | B14: =COUNTIF(Savollar!$C$2:$C$26,"O'rta") -> 18 | C14: =COUNTIFS(Savollar!$C$2:$C$26,"O'rta",Savollar!$L$2:$L$26,"To'g'ri") -> 0 | D14: =IFERROR(ROUND(C14/B14*100,0),"") -> 0 | E14: 2
A15: Qiyin | B15: =COUNTIF(Savollar!$C$2:$C$26,"Qiyin") -> 5 | C15: =COUNTIFS(Savollar!$C$2:$C$26,"Qiyin",Savollar!$L$2:$L$26,"To'g'ri") -> 0 | D15: =IFERROR(ROUND(C15/B15*100,0),"") -> 0 | E15: 3
A16: KDI (Bilim chuqurligi indeksi) | B16: =IFERROR(ROUND((C13*1+C14*2+C15*3)/(B13*1+B14*2+B15*3)*100,0),"") -> 0 | E16: Og'irlikli: (to'g'ri x og'.) / (jami x og'.) x 100
A17: Bilim darajasi (Mastery) | B17: =IF(B16="","",IF(B16>=95,"A'lo (Exceptional)",IF(B16>=85,"Juda yaxshi (Advanced)",IF(B16>=70,"Yaxshi (Proficient)",IF(B16>=55,"Asosiy (Basic)",IF(B16>=40,"Yuzaki (Limited)","Jiddiy qo'llab")))))) -> Jiddiy qo'llab
A19: SALOHIYAT (shaffof formula)
A20: Salohiyat (Potential) | B20: =IFERROR(ROUND((B9+B16+D15)/3,0),"") -> 0 | E20: (Tuzatilgan + KDI + Qiyin%) / 3 — ishonch: o'rta. Qo'lda emas, formuladan.
A22: STRANDLAR (fan bloklari)
A23: Toifa | B23: Savollar (n) | C23: To'g'ri | D23: Foiz %
A24: Son va amallar | B24: =COUNTIF(Savollar!$D$2:$D$26,"Son va amallar") -> 16 | C24: =COUNTIFS(Savollar!$D$2:$D$26,"Son va amallar",Savollar!$L$2:$L$26,"To'g'ri") -> 0 | D24: =IFERROR(ROUND(C24/B24*100,0),"") -> 0
A25: Geometriya va o'lchov | B25: =COUNTIF(Savollar!$D$2:$D$26,"Geometriya va o'lchov") -> 6 | C25: =COUNTIFS(Savollar!$D$2:$D$26,"Geometriya va o'lchov",Savollar!$L$2:$L$26,"To'g'ri") -> 0 | D25: =IFERROR(ROUND(C25/B25*100,0),"") -> 0
A26: Mantiq va muammo yechish | B26: =COUNTIF(Savollar!$D$2:$D$26,"Mantiq va muammo yechish") -> 3 | C26: =COUNTIFS(Savollar!$D$2:$D$26,"Mantiq va muammo yechish",Savollar!$L$2:$L$26,"To'g'ri") -> 0 | D26: =IFERROR(ROUND(C26/B26*100,0),"") -> 0
A28: MAVZU (issiqlik xaritasi)
A29: Toifa | B29: Savollar (n) | C29: To'g'ri | D29: Foiz %
A30: Joy qiymati | B30: =COUNTIF(Savollar!$E$2:$E$26,"Joy qiymati") -> 0 | C30: =COUNTIFS(Savollar!$E$2:$E$26,"Joy qiymati",Savollar!$L$2:$L$26,"To'g'ri") -> 0 | D30: =IFERROR(ROUND(C30/B30*100,0),"")
A31: Arifmetika | B31: =COUNTIF(Savollar!$E$2:$E$26,"Arifmetika") -> 0 | C31: =COUNTIFS(Savollar!$E$2:$E$26,"Arifmetika",Savollar!$L$2:$L$26,"To'g'ri") -> 0 | D31: =IFERROR(ROUND(C31/B31*100,0),"")
A32: O'nli kasr | B32: =COUNTIF(Savollar!$E$2:$E$26,"O'nli kasr") -> 1 | C32: =COUNTIFS(Savollar!$E$2:$E$26,"O'nli kasr",Savollar!$L$2:$L$26,"To'g'ri") -> 0 | D32: =IFERROR(ROUND(C32/B32*100,0),"") -> 0
A33: Foiz | B33: =COUNTIF(Savollar!$E$2:$E$26,"Foiz") -> 3 | C33: =COUNTIFS(Savollar!$E$2:$E$26,"Foiz",Savollar!$L$2:$L$26,"To'g'ri") -> 0 | D33: =IFERROR(ROUND(C33/B33*100,0),"") -> 0
A34: Kasr amallari | B34: =COUNTIF(Savollar!$E$2:$E$26,"Kasr amallari") -> 4 | C34: =COUNTIFS(Savollar!$E$2:$E$26,"Kasr amallari",Savollar!$L$2:$L$26,"To'g'ri") -> 0 | D34: =IFERROR(ROUND(C34/B34*100,0),"") -> 0
A35: O'lchash | B35: =COUNTIF(Savollar!$E$2:$E$26,"O'lchash") -> 0 | C35: =COUNTIFS(Savollar!$E$2:$E$26,"O'lchash",Savollar!$L$2:$L$26,"To'g'ri") -> 0 | D35: =IFERROR(ROUND(C35/B35*100,0),"")
A36: Geometriya | B36: =COUNTIF(Savollar!$E$2:$E$26,"Geometriya") -> 6 | C36: =COUNTIFS(Savollar!$E$2:$E$26,"Geometriya",Savollar!$L$2:$L$26,"To'g'ri") -> 0 | D36: =IFERROR(ROUND(C36/B36*100,0),"") -> 0
A37: Qonuniyat | B37: =COUNTIF(Savollar!$E$2:$E$26,"Qonuniyat") -> 1 | C37: =COUNTIFS(Savollar!$E$2:$E$26,"Qonuniyat",Savollar!$L$2:$L$26,"To'g'ri") -> 0 | D37: =IFERROR(ROUND(C37/B37*100,0),"") -> 0
A38: Nisbat va proporsiya | B38: =COUNTIF(Savollar!$E$2:$E$26,"Nisbat va proporsiya") -> 4 | C38: =COUNTIFS(Savollar!$E$2:$E$26,"Nisbat va proporsiya",Savollar!$L$2:$L$26,"To'g'ri") -> 0 | D38: =IFERROR(ROUND(C38/B38*100,0),"") -> 0
A39: So'zli masala | B39: =COUNTIF(Savollar!$E$2:$E$26,"So'zli masala") -> 2 | C39: =COUNTIFS(Savollar!$E$2:$E$26,"So'zli masala",Savollar!$L$2:$L$26,"To'g'ri") -> 0 | D39: =IFERROR(ROUND(C39/B39*100,0),"") -> 0
A40: Algebra | B40: =COUNTIF(Savollar!$E$2:$E$26,"Algebra") -> 4 | C40: =COUNTIFS(Savollar!$E$2:$E$26,"Algebra",Savollar!$L$2:$L$26,"To'g'ri") -> 0 | D40: =IFERROR(ROUND(C40/B40*100,0),"") -> 0
A41: ASOSIY KO'NIKMA (radar)
A42: Toifa | B42: Savollar (n) | C42: To'g'ri | D42: Foiz %
A43: Protsedural ravonlik | B43: =COUNTIF(Savollar!$G$2:$G$26,"Protsedural ravonlik") -> 8 | C43: =COUNTIFS(Savollar!$G$2:$G$26,"Protsedural ravonlik",Savollar!$L$2:$L$26,"To'g'ri") -> 0 | D43: =IFERROR(ROUND(C43/B43*100,0),"") -> 0
A44: Konseptual tushunish | B44: =COUNTIF(Savollar!$G$2:$G$26,"Konseptual tushunish") -> 9 | C44: =COUNTIFS(Savollar!$G$2:$G$26,"Konseptual tushunish",Savollar!$L$2:$L$26,"To'g'ri") -> 0 | D44: =IFERROR(ROUND(C44/B44*100,0),"") -> 0
A45: Muammo yechish | B45: =COUNTIF(Savollar!$G$2:$G$26,"Muammo yechish") -> 3 | C45: =COUNTIFS(Savollar!$G$2:$G$26,"Muammo yechish",Savollar!$L$2:$L$26,"To'g'ri") -> 0 | D45: =IFERROR(ROUND(C45/B45*100,0),"") -> 0
...

Sheet Indikator_xaritasi
A1: QOIDA: har bir raqam faqat shu label'lardan chiqadi. Label yo'q bo'lsa — indikator berilmaydi yoki sifatli (past ishonch) ko'rsatiladi.
A2: Indikator | B2: Manba label(lar) | C2: Hisoblash qoidasi | D2: Holat
A3: Joriy ball / foiz | B3: Olingan ball, Ball | C3: Olingan ball yig'indisi; foiz = olingan/jami x 100 | D3: Hisoblanadi
A4: Qiyinchilik foizlari | B4: Qiyinchilik + Natija | C4: Har toifa: to'g'ri / jami x 100 | D4: Hisoblanadi
A5: KDI (bilim chuqurligi) | B5: Qiyinchilik + Natija | C5: Og'irlikli: (to'g'ri x [1/2/3]) / (jami x [1/2/3]) x 100 | D5: Hisoblanadi
A6: Bilim darajasi (Mastery) | B6: KDI | C6: KDI -> 6 toifadan biri | D6: Hisoblanadi
A7: Tuzatilgan baho | B7: Xato turi + Ball | C7: Xom ball + 'Texnik' deb belgilangan ballar | D7: Hisoblanadi
A8: Mavzu heatmap | B8: Mavzu + Natija | C8: Har mavzu: to'g'ri / jami x 100 | D8: Hisoblanadi
A9: Strand ballari | B9: Strand + Natija | C9: Har strand: to'g'ri / jami x 100 | D9: Hisoblanadi
A10: Skill radar | B10: Asosiy ko'nikma + Natija | C10: Har ko'nikma: to'g'ri / jami | D10: Shartli (n>=3)
A11: Bloom profil | B11: Bloom + Natija | C11: Har daraja: to'g'ri / jami | D11: Hisoblanadi
A12: Fikrlash (ded/ind/anal) | B12: Fikrlash turi + Natija | C12: Har tur: to'g'ri / jami | D12: Shartli (n>=3)
A13: Gap (past/da/yuqori) | B13: Sinf darajasi + Natija | C13: Zonalar bo'yicha to'g'ri / jami | D13: Hisoblanadi
... A18: Percentile / Guruh o'rtachasi | B18: (kohort kerak) | C18: Norma ma'lumoti yo'q | D18: DROP — kohort yopilgach

Sheet Royxatlar
A1: Qiyinchilik | B1: Strand | C1: Mavzu | D1: Asosiy ko'nikma | E1: Bloom darajasi | F1: Fikrlash turi | G1: Sinf darajasi | H1: Xalqaro framework | I1: Natija | J1: Xato turi
A2: Oson | B2: Son va amallar | C2: Joy qiymati | D2: Protsedural ravonlik | E2: Eslab qolish | F2: Deduktiv | G2: 7-dan past | H2: PISA: Miqdor | I2: To'g'ri | J2: Yo'q
A3: O'rta | B3: Geometriya va o'lchov | C3: Arifmetika | D3: Konseptual tushunish | E3: Tushunish | F3: Induktiv | G3: 7-sinf | H3: PISA: O'zgarish | I3: Noto'g'ri | J3: Texnik
A4: Qiyin | B4: Mantiq va muammo yechish | C4: O'nli kasr | D4: Muammo yechish | E4: Qo'llash | F4: Analitik | G4: 7-dan yuqori | H4: PISA: Fazo va shakl | I4: Qisman | J4: Bilim bo'shlig'i
C5: Foiz | D5: Mantiqiy xulosa | E5: Tahlil | F5: Fazoviy | H5: PISA: Noaniqlik
C6: Kasr amallari | D6: Fazoviy fikrlash | E6: Baholash | F6: Yo'q | H6: TIMSS: Number
C7: O'lchash | D7: Modellashtirish | E7: Yaratish | H7: TIMSS: Algebra
C8: Geometriya | D8: Hisoblash aniqligi | H8: TIMSS: Geometry
C9: Qonuniyat | H9: TIMSS: Data
C10: Nisbat va proporsiya | H10: Kangaroo: Arifmetika
C11: So'zli masala | H11: Kangaroo: Mantiq
C12: Algebra | H12: Kangaroo: Geometriya
H13: Yo'q
